{
    "expand": "operations,versionedRepresentations,editmeta,changelog,renderedFields",
    "fields": {
        "aggregateprogress": {
            "progress": 0,
            "total": 0
        },
        "aggregatetimeestimate": null,
        "aggregatetimeoriginalestimate": null,
        "aggregatetimespent": null,
        "assignee": null,
        "components": [{
            "description": "Tracks issues related to HiveServer2",
            "id": "12320408",
            "name": "HiveServer2",
            "self": "https://issues.apache.org/jira/rest/api/2/component/12320408"
        }],
        "created": "2016-09-08T18:54:47.000+0000",
        "creator": {
            "active": true,
            "avatarUrls": {
                "16x16": "https://issues.apache.org/jira/secure/useravatar?size=xsmall&avatarId=10452",
                "24x24": "https://issues.apache.org/jira/secure/useravatar?size=small&avatarId=10452",
                "32x32": "https://issues.apache.org/jira/secure/useravatar?size=medium&avatarId=10452",
                "48x48": "https://issues.apache.org/jira/secure/useravatar?avatarId=10452"
            },
            "displayName": "Shreyas Joshi",
            "key": "shreyasjoshis",
            "name": "shreyasjoshis",
            "self": "https://issues.apache.org/jira/rest/api/2/user?username=shreyasjoshis",
            "timeZone": "Etc/UTC"
        },
        "customfield_10010": null,
        "customfield_12310191": null,
        "customfield_12310192": null,
        "customfield_12310220": null,
        "customfield_12310222": "1_*:*_1_*:*_285236_*|*_5_*:*_1_*:*_0",
        "customfield_12310230": null,
        "customfield_12310250": null,
        "customfield_12310290": null,
        "customfield_12310291": null,
        "customfield_12310300": null,
        "customfield_12310310": "0.0",
        "customfield_12310320": null,
        "customfield_12310420": "9223372036854775807",
        "customfield_12310920": "9223372036854775807",
        "customfield_12310921": null,
        "customfield_12311020": null,
        "customfield_12311024": null,
        "customfield_12311120": null,
        "customfield_12311820": "0|i33erj:",
        "customfield_12312022": null,
        "customfield_12312023": null,
        "customfield_12312024": null,
        "customfield_12312026": null,
        "customfield_12312220": null,
        "customfield_12312320": null,
        "customfield_12312321": null,
        "customfield_12312322": null,
        "customfield_12312323": null,
        "customfield_12312324": null,
        "customfield_12312325": null,
        "customfield_12312326": null,
        "customfield_12312327": null,
        "customfield_12312328": null,
        "customfield_12312329": null,
        "customfield_12312330": null,
        "customfield_12312331": null,
        "customfield_12312332": null,
        "customfield_12312333": null,
        "customfield_12312334": null,
        "customfield_12312335": null,
        "customfield_12312336": null,
        "customfield_12312337": null,
        "customfield_12312338": null,
        "customfield_12312339": null,
        "customfield_12312340": null,
        "customfield_12312341": null,
        "customfield_12312520": null,
        "customfield_12312521": "Thu Sep 08 18:58:22 UTC 2016",
        "customfield_12312720": null,
        "customfield_12312823": null,
        "customfield_12312920": null,
        "customfield_12312921": null,
        "customfield_12312923": null,
        "customfield_12313422": "false",
        "customfield_12313520": null,
        "description": "h3. Summary\n{{HiveServer2Hook}} Seems to be ignoring the auth_mechanism when the user is not specified. I am not entirely sure if the solution should be should change impyala or Airflow.\n\nh3. Reproducing the problem\nWith this connection string for Hive: {{AIRFLOW_CONN_GH_HIVE=hive2://@localhost:10000/}} (No user name and no password)\n\n I get the following error from {{HiveServer2hook}}:\n\n{code}\nfrom airflow.hooks import HiveServer2Hook\nhive_hook = HiveServer2Hook (hiveserver2_conn_id='GH_HIVE')\n{code}\n\n{noformat}\n[2016-09-08 14:30:52,420] {base_hook.py:53} INFO - Using connection to: localhost\nTraceback (most recent call last):\n  File \"<stdin>\", line 1, in <module>\n  File \"/Users/shreyasjoshis/python-envs/default-env/lib/python3.5/site-packages/airflow/hooks/hive_hooks.py\", line 464, in get_conn\n    database=db.schema or 'default')\n  File \"/Users/shreyasjoshis/python-envs/default-env/lib/python3.5/site-packages/impala/dbapi.py\", line 147, in connect\n    auth_mechanism=auth_mechanism)\n  File \"/Users/shreyasjoshis/python-envs/default-env/lib/python3.5/site-packages/impala/hiveserver2.py\", line 658, in connect\n    transport.open()\n  File \"/Users/shreyasjoshis/python-envs/default-env/lib/python3.5/site-packages/thrift_sasl/__init__.py\", line 72, in open\n    message=(\"Could not start SASL: %s\" % self.sasl.getError()))\nthriftpy.transport.TTransportException: TTransportException(type=1, message=\"Could not start SASL: b'Error in sasl_client_start (-4) SASL(-4): no mechanism available: No worthy mechs found'\")\n{noformat}\n\nh3. More detail\n[Here|https://github.com/apache/incubator-airflow/blob/master/airflow/hooks/hive_hooks.py#L591] {{db.login}} ends up being an empty string rather than {{None}}. This seems to cause impala to try sasl. Changing {{db.login}} from an empty string to {{None}} seems to fix the issue. \n\nSo, the following does not work\n\n{code}\nfrom impala.dbapi import connect\nconnect (host='localhost', port=10000, user='', auth_mechanism='PLAIN', database= 'default')\n{code}\n\nThe error is:\n{noformat}\nTraceback (most recent call last):\n  File \"<stdin>\", line 1, in <module>\n  File \"/Users/shreyasjoshis/python-envs/default-env/lib/python3.5/site-packages/impala/dbapi.py\", line 147, in connect\n    auth_mechanism=auth_mechanism)\n  File \"/Users/shreyasjoshis/python-envs/default-env/lib/python3.5/site-packages/impala/hiveserver2.py\", line 658, in connect\n    transport.open()\n  File \"/Users/shreyasjoshis/python-envs/default-env/lib/python3.5/site-packages/thrift_sasl/__init__.py\", line 72, in open\n    message=(\"Could not start SASL: %s\" % self.sasl.getError()))\nthriftpy.transport.TTransportException: TTransportException(type=1, message=\"Could not start SASL: b'Error in sasl_client_start (-4) SASL(-4): no mechanism available: No worthy mechs found'\")\n{noformat}\n\nBut the following does:\n\n{code}\nfrom impala.dbapi import connect\nconnect (host='localhost', port=10000, user=None, auth_mechanism='PLAIN', database= 'default')\n{code}",
        "duedate": null,
        "environment": null,
        "fixVersions": [],
        "issuelinks": [],
        "issuetype": {
            "avatarId": 21133,
            "description": "A problem which impairs or prevents the functions of the product.",
            "iconUrl": "https://issues.apache.org/jira/secure/viewavatar?size=xsmall&avatarId=21133&avatarType=issuetype",
            "id": "1",
            "name": "Bug",
            "self": "https://issues.apache.org/jira/rest/api/2/issuetype/1",
            "subtask": false
        },
        "labels": [],
        "lastViewed": null,
        "priority": {
            "iconUrl": "https://issues.apache.org/jira/images/icons/priorities/major.svg",
            "id": "3",
            "name": "Major",
            "self": "https://issues.apache.org/jira/rest/api/2/priority/3"
        },
        "progress": {
            "progress": 0,
            "total": 0
        },
        "project": {
            "avatarUrls": {
                "16x16": "https://issues.apache.org/jira/secure/projectavatar?size=xsmall&pid=12310843&avatarId=11935",
                "24x24": "https://issues.apache.org/jira/secure/projectavatar?size=small&pid=12310843&avatarId=11935",
                "32x32": "https://issues.apache.org/jira/secure/projectavatar?size=medium&pid=12310843&avatarId=11935",
                "48x48": "https://issues.apache.org/jira/secure/projectavatar?pid=12310843&avatarId=11935"
            },
            "id": "12310843",
            "key": "HIVE",
            "name": "Hive",
            "projectCategory": {
                "description": "Scalable Distributed Computing",
                "id": "10292",
                "name": "Hadoop",
                "self": "https://issues.apache.org/jira/rest/api/2/projectCategory/10292"
            },
            "self": "https://issues.apache.org/jira/rest/api/2/project/12310843"
        },
        "reporter": {
            "active": true,
            "avatarUrls": {
                "16x16": "https://issues.apache.org/jira/secure/useravatar?size=xsmall&avatarId=10452",
                "24x24": "https://issues.apache.org/jira/secure/useravatar?size=small&avatarId=10452",
                "32x32": "https://issues.apache.org/jira/secure/useravatar?size=medium&avatarId=10452",
                "48x48": "https://issues.apache.org/jira/secure/useravatar?avatarId=10452"
            },
            "displayName": "Shreyas Joshi",
            "key": "shreyasjoshis",
            "name": "shreyasjoshis",
            "self": "https://issues.apache.org/jira/rest/api/2/user?username=shreyasjoshis",
            "timeZone": "Etc/UTC"
        },
        "resolution": {
            "description": "The problem isn't valid and it can't be fixed.",
            "id": "6",
            "name": "Invalid",
            "self": "https://issues.apache.org/jira/rest/api/2/resolution/6"
        },
        "resolutiondate": "2016-09-08T18:59:32.000+0000",
        "status": {
            "description": "A resolution has been taken, and it is awaiting verification by reporter. From here issues are either reopened, or are closed.",
            "iconUrl": "https://issues.apache.org/jira/images/icons/statuses/resolved.png",
            "id": "5",
            "name": "Resolved",
            "self": "https://issues.apache.org/jira/rest/api/2/status/5",
            "statusCategory": {
                "colorName": "green",
                "id": 3,
                "key": "done",
                "name": "Done",
                "self": "https://issues.apache.org/jira/rest/api/2/statuscategory/3"
            }
        },
        "subtasks": [],
        "summary": "HiveServer2Hook invokes incorrect Auth mechanism when user not specified",
        "timeestimate": null,
        "timeoriginalestimate": null,
        "timespent": null,
        "updated": "2016-09-08T18:59:33.000+0000",
        "versions": [],
        "votes": {
            "hasVoted": false,
            "self": "https://issues.apache.org/jira/rest/api/2/issue/HIVE-14725/votes",
            "votes": 0
        },
        "watches": {
            "isWatching": false,
            "self": "https://issues.apache.org/jira/rest/api/2/issue/HIVE-14725/watchers",
            "watchCount": 1
        },
        "workratio": -1
    },
    "id": "13003663",
    "key": "HIVE-14725",
    "self": "https://issues.apache.org/jira/rest/api/2/issue/13003663"
}